Workbook

Sheet UIT3561
A1: Sri Sivasubramaniya Nadar College of Engineering, Kalavakkam - 603 110
A2: Department of Information Technology
A3: ATTENDANCE SHEET
A4: Class & Section : V SEM IT B
A5: Academic Year: 2026-2027 | AW5: Batch : 2024-28
A7: Sub Code & Sub Name : UIT3561 -Full Stack Web Development | AV7: ug2024-it@ssn.edu.in
A8: Staff Name : Mr. Sankar Santhamoorthy(T) & Dr. K. R. Uthayan
F9: Mark "P" for presentees , "A" for absentees
A11: S.No | B11: Digital Id | C11: Register Number | D11: Name as per 12th Mark Sheet | E11: SSN Email ID | F11: Date
F12: 24/7/26 | G12: 24/7/26 | H12: 31/7/26 | I12: 31/7/26 | J12: 10/09/26 3rd Hour | BJ12: =COUNTA(F12:BI12)
A13: 1 | B13: 2410606 | C13: 3122245002067 | D13: Pragalya T | E13: pragalya2410606@ssn.edu.in | F13: A | G13: A | H13: P | I13: P | J13: A | BJ13: =COUNTIF(F13:BI13,"P") | BK13: =SUM((BJ13/BJ12)*100)
A14: 2 | B14: 2410674 | C14: 3122245002068 | D14: Praghathish G T | E14: praghathish2410674@ssn.edu.in | F14: A | G14: A | H14: P | I14: P | J14: P | BJ14: =COUNTIF(F14:BI14,"P") | BK14: =SUM((BJ14/BJ12)*100)
A15: 3 | B15: 2410080 | C15: 3122245002069 | D15: Pranav C K | E15: pranav2410080@ssn.edu.in | F15: A | G15: A | H15: A | I15: A | J15: P | BJ15: =COUNTIF(F15:BI15,"P") | BK15: =SUM((BJ15/BJ12)*100)
A16: 4 | B16: 2410328 | C16: 3122245002070 | D16: Pranav Vasudevan | E16: pranav2410328@ssn.edu.in | F16: P | G16: P | H16: A | I16: A | J16: P | BJ16: =COUNTIF(F16:BI16,"P") | BK16: =SUM((BJ16/BJ12)*100)
A17: 5 | B17: 2410738 | C17: 3122245002071 | D17: Radhakrishnan M | E17: radhakrishnan2410738@ssn.edu.in | F17: P | G17: P | H17: A | I17: A | J17: P | BJ17: =COUNTIF(F17:BI17,"P") | BK17: =SUM((BJ17/BJ12)*100)
A18: 6 | B18: 2410786 | C18: 3122245002072 | D18: Raghul Krishna V | E18: raghulkrishna2410786@ssn.edu.in | F18: A | G18: A | H18: A | I18: A | J18: P | BJ18: =COUNTIF(F18:BI18,"P") | BK18: =SUM((BJ18/BJ12)*100)
A19: 7 | B19: 2410441 | C19: 3122245002073 | D19: Ragul A | E19: ragul2410441@ssn.edu.in | F19: A | G19: A | H19: P | I19: P | J19: P | BJ19: =COUNTIF(F19:BI19,"P") | BK19: =SUM((BJ19/BJ12)*100)
A20: 8 | B20: 2410834 | C20: 3122245002074 | D20: Ragunandhan M | E20: ragunandhan2410834@ssn.edu.in | F20: P | G20: P | H20: P | I20: P | J20: P | BJ20: =COUNTIF(F20:BI20,"P") | BK20: =SUM((BJ20/BJ12)*100)
A21: 9 | B21: 2410098 | C21: 3122245002075 | D21: Rajkumar M | E21: rajkumar2410098@ssn.edu.in | F21: A | G21: A | H21: P | I21: P | J21: P | BJ21: =COUNTIF(F21:BI21,"P") | BK21: =SUM((BJ21/BJ12)*100)
A22: 10 | B22: 2410632 | C22: 3122245002076 | D22: Ramakrishnan M R | E22: ramakrishnan2410632@ssn.edu.in | F22: A | G22: A | H22: P | I22: P | J22: P | BJ22: =COUNTIF(F22:BI22,"P") | BK22: =SUM((BJ22/BJ12)*100)
A23: 11 | B23: 2410313 | C23: 3122245002077 | D23: Raveena V K | E23: raveena2410313@ssn.edu.in | F23: A | G23: A | H23: A | I23: A | J23: P | BJ23: =COUNTIF(F23:BI23,"P") | BK23: =SUM((BJ23/BJ12)*100)
A24: 12 | B24: 2410581 | C24: 3122245002078 | D24: Ridhi R | E24: ridhi2410581@ssn.edu.in | F24: A | G24: A | H24: P | I24: P | J24: P | BJ24: =COUNTIF(F24:BI24,"P") | BK24: =SUM((BJ24/BJ12)*100)
A25: 13 | B25: 2410343 | C25: 3122245002079 | D25: Rishikumar Pitchiah Kalyanakumar | E25: rishikumar2410343@ssn.edu.in | F25: P | G25: P | H25: P | I25: P | J25: P | BJ25: =COUNTIF(F25:BI25,"P") | BK25: =SUM((BJ25/BJ12)*100)
A26: 14 | B26: 2410308 | C26: 3122245002080 | D26: Rithin Asvathama V | E26: rithinasvathama2410308@ssn.edu.in | F26: P | G26: P | H26: A | I26: A | J26: A | BJ26: =COUNTIF(F26:BI26,"P") | BK26: =SUM((BJ26/BJ12)*100)
A27: 15 | B27: 2410445 | C27: 3122245002081 | D27: Ritvik Kumar T | E27: ritvikkumar2410445@ssn.edu.in | F27: P | G27: P | H27: P | I27: P | J27: P | BJ27: =COUNTIF(F27:BI27,"P") | BK27: =SUM((BJ27/BJ12)*100)
A28: 16 | B28: 2410230 | C28: 3122245002082 | D28: Roja Sri R | E28: rojasri2410230@ssn.edu.in | F28: A | G28: A | H28: P | I28: P | J28: P | BJ28: =COUNTIF(F28:BI28,"P") | BK28: =SUM((BJ28/BJ12)*100)
A29: 17 | B29: 2410331 | C29: 3122245002083 | D29: Rovena Madharasi I | E29: rovenamadharasi2410331@ssn.edu.in | F29: P | G29: P | H29: P | I29: P | J29: P | BJ29: =COUNTIF(F29:BI29,"P") | BK29: =SUM((BJ29/BJ12)*100)
A30: 18 | B30: 2410229 | C30: 3122245002084 | D30: Sabarish S B | E30: sabarish2410229@ssn.edu.in | F30: A | G30: A | H30: A | I30: A | J30: P | BJ30: =COUNTIF(F30:BI30,"P") | BK30: =SUM((BJ30/BJ12)*100)
A31: 19 | B31: 2410984 | C31: 3122245002085 | D31: Sahana A | E31: sahana2410984@ssn.edu.in | F31: P | G31: P | H31: P | I31: P | J31: P | BJ31: =COUNTIF(F31:BI31,"P") | BK31: =SUM((BJ31/BJ12)*100)
A32: 20 | B32: 2410091 | C32: 3122245002086 | D32: Sandhya B | E32: sandhya2410091@ssn.edu.in | F32: A | G32: A | H32: P | I32: P | J32: P | BJ32: =COUNTIF(F32:BI32,"P") | BK32: =SUM((BJ32/BJ12)*100)
A33: 21 | B33: 2410706 | C33: 3122245002087 | D33: Sandhya S | E33: sandhya2410706@ssn.edu.in | F33: A | G33: A | H33: P | I33: P | J33: P | BJ33: =COUNTIF(F33:BI33,"P") | BK33: =SUM((BJ33/BJ12)*100)
A34: 22 | B34: 2410778 | C34: 3122245002088 | D34: Sangaraju Sathwik | E34: sangaraju2410778@ssn.edu.in | F34: A | G34: A | H34: A | I34: A | J34: P | BJ34: =COUNTIF(F34:BI34,"P") | BK34: =SUM((BJ34/BJ12)*100)
A35: 23 | B35: 2410162 | C35: 3122245002089 | D35: Sanjana Shankar | E35: sanjana2410162@ssn.edu.in | F35: A | G35: A | H35: A | I35: A | J35: P | BJ35: =COUNTIF(F35:BI35,"P") | BK35: =SUM((BJ35/BJ12)*100)
A36: 24 | B36: 2410514 | C36: 3122245002090 | D36: Sanjay J | E36: sanjay2410514@ssn.edu.in | F36: A | G36: A | H36: A | I36: A | J36: P | BJ36: =COUNTIF(F36:BI36,"P") | BK36: =SUM((BJ36/BJ12)*100)
A37: 25 | B37: 2410068 | C37: 3122245002091 | D37: Sanjay Raam S | E37: sanjayraam2410068@ssn.edu.in | F37: P | G37: P | H37: A | I37: A | J37: P | BJ37: =COUNTIF(F37:BI37,"P") | BK37: =SUM((BJ37/BJ12)*100)
A38: 26 | B38: 2410185 | C38: 3122245002092 | D38: Sanjay T | E38: sanjay2410185@ssn.edu.in | F38: A | G38: A | H38: P | I38: P | J38: P | BJ38: =COUNTIF(F38:BI38,"P") | BK38: =SUM((BJ38/BJ12)*100)
A39: 27 | B39: 2410988 | C39: 3122245002093 | D39: Santhosh Aaron C | E39: santhosh2410988@ssn.edu.in | F39: A | G39: A | H39: P | I39: P | J39: P | BJ39: =COUNTIF(F39:BI39,"P") | BK39: =SUM((BJ39/BJ12)*100)
A40: 28 | B40: 2410488 | C40: 3122245002094 | D40: Sarvesh K | E40: sarvesh2410488@ssn.edu.in | F40: A | G40: A | H40: A | I40: A | J40: P | BJ40: =COUNTIF(F40:BI40,"P") | BK40: =SUM((BJ40/BJ12)*100)
A41: 29 | B41: 2410076 | C41: 3122245002095 | D41: Sarvesh S | E41: sarvesh2410076@ssn.edu.in | F41: P | G41: P | H41: P | I41: P | J41: P | BJ41: =COUNTIF(F41:BI41,"P") | BK41: =SUM((BJ41/BJ12)*100)
A42: 30 | B42: 2410740 | C42: 3122245002096 | D42: Sarvesh S | E42: sarvesh2410740@ssn.edu.in | F42: A | G42: A | H42: P | I42: P | J42: P | BJ42: =COUNTIF(F42:BI42,"P") | BK42: =SUM((BJ42/BJ12)*100)
...

Sheet UIT3562
A1: Sri Sivasubramaniya Nadar College of Engineering, Kalavakkam - 603 110
A2: Department of Information Technology
A3: ATTENDANCE SHEET
A4: Class & Section : V SEM IT B
A5: Academic Year: 2026-2027 | AY5: Batch : 2024-28
A7: Sub Code & Sub Name : UIT3562 - Principles of Operating Systems | AX7: ug2024-it@ssn.edu.in
A8: Staff Name : Dr. I. Joe Louis Paul
F10: Mark "P" for presentees , "A" for absentees
A11: S.No | B11: Digital Id | C11: Register Number | D11: Name as per 12th Mark Sheet | E11: SSN Email ID | F11: Date
F12: 29/06/26 1st Hour | G12: 30/06/26 4th Hour | H12: 01/07/26 3rd Hour | I12: 13/07/26 1st Hour | J12: 13/07/26 2nd Hour | K12: 14/07/26 4th Hour | L12: 15/07/26 3rd Hour | M12: 15/07/26 4th Hour | N12: 20/07 1st Hour | O12: 21/07 4th Hour | P12: 22/07 3rd Hour | Q12: 27/07 1st Hour | R12: 28/07 4th Hour | S12: 29/07 3rd Hour | T12: 03/08 1st Hour | U12: 04/08 4th Hour | V12: 11/08 4th Hour | W12: 12/08 3rd Hour | X12: 17/08 1st Hour | BL12: =COUNTA(F12:BK12)
A13: 1 | B13: 2410606 | C13: 3122245002067 | D13: Pragalya T | E13: pragalya2410606@ssn.edu.in | F13: A | G13: P | H13: P | I13: P | J13: P | K13: P | L13: P | M13: P | N13: A | O13: P | P13: P | Q13: P | R13: P | S13: P | T13: A | U13: P | V13: P | W13: A | X13: A | BL13: =COUNTIF(F13:BK13,"P") | BM13: =SUM((BL13/BL12)*100)
A14: 2 | B14: 2410674 | C14: 3122245002068 | D14: Praghathish G T | E14: praghathish2410674@ssn.edu.in | F14: P | G14: P | H14: P | I14: P | J14: P | K14: P | L14: P | M14: P | N14: A | O14: P | P14: A | Q14: P | R14: P | S14: P | T14: P | U14: P | V14: P | W14: A | X14: P | BL14: =COUNTIF(F14:BK14,"P") | BM14: =SUM((BL14/BL12)*100)
A15: 3 | B15: 2410080 | C15: 3122245002069 | D15: Pranav C K | E15: pranav2410080@ssn.edu.in | F15: P | G15: A | H15: A | I15: P | J15: P | K15: P | L15: A | M15: A | N15: A | O15: P | P15: A | Q15: A | R15: A | S15: P | T15: A | U15: P | V15: P | W15: A | X15: A | BL15: =COUNTIF(F15:BK15,"P") | BM15: =SUM((BL15/BL12)*100)
A16: 4 | B16: 2410328 | C16: 3122245002070 | D16: Pranav Vasudevan | E16: pranav2410328@ssn.edu.in | F16: P | G16: P | H16: P | I16: A | J16: A | K16: A | L16: P | M16: P | N16: A | O16: P | P16: P | Q16: A | R16: P | S16: P | T16: A | U16: P | V16: P | W16: A | X16: P | BL16: =COUNTIF(F16:BK16,"P") | BM16: =SUM((BL16/BL12)*100)
A17: 5 | B17: 2410738 | C17: 3122245002071 | D17: Radhakrishnan M | E17: radhakrishnan2410738@ssn.edu.in | F17: P | G17: P | H17: A | I17: P | J17: P | K17: A | L17: P | M17: P | N17: A | O17: P | P17: P | Q17: P | R17: P | S17: A | T17: A | U17: A | V17: A | W17: A | X17: P | BL17: =COUNTIF(F17:BK17,"P") | BM17: =SUM((BL17/BL12)*100)
A18: 6 | B18: 2410786 | C18: 3122245002072 | D18: Raghul Krishna V | E18: raghulkrishna2410786@ssn.edu.in | F18: P | G18: A | H18: P | I18: A | J18: A | K18: P | L18: P | M18: P | N18: A | O18: P | P18: P | Q18: P | R18: P | S18: P | T18: P | U18: A | V18: P | W18: P | X18: P | BL18: =COUNTIF(F18:BK18,"P") | BM18: =SUM((BL18/BL12)*100)
A19: 7 | B19: 2410441 | C19: 3122245002073 | D19: Ragul A | E19: ragul2410441@ssn.edu.in | F19: P | G19: P | H19: P | I19: P | J19: P | K19: P | L19: P | M19: P | N19: A | O19: P | P19: P | Q19: P | R19: P | S19: P | T19: P | U19: P | V19: P | W19: P | X19: A | BL19: =COUNTIF(F19:BK19,"P") | BM19: =SUM((BL19/BL12)*100)
A20: 8 | B20: 2410834 | C20: 3122245002074 | D20: Ragunandhan M | E20: ragunandhan2410834@ssn.edu.in | F20: P | G20: P | H20: P | I20: P | J20: P | K20: P | L20: P | M20: P | N20: P | O20: P | P20: P | Q20: P | R20: P | S20: P | T20: P | U20: P | V20: P | W20: P | X20: P | BL20: =COUNTIF(F20:BK20,"P") | BM20: =SUM((BL20/BL12)*100)
A21: 9 | B21: 2410098 | C21: 3122245002075 | D21: Rajkumar M | E21: rajkumar2410098@ssn.edu.in | F21: P | G21: P | H21: P | I21: P | J21: P | K21: P | L21: A | M21: A | N21: A | O21: P | P21: P | Q21: P | R21: A | S21: A | T21: P | U21: P | V21: P | W21: A | X21: A | BL21: =COUNTIF(F21:BK21,"P") | BM21: =SUM((BL21/BL12)*100)
A22: 10 | B22: 2410632 | C22: 3122245002076 | D22: Ramakrishnan M R | E22: ramakrishnan2410632@ssn.edu.in | F22: P | G22: P | H22: P | I22: P | J22: P | K22: P | L22: A | M22: A | N22: P | O22: P | P22: P | Q22: P | R22: P | S22: P | T22: P | U22: P | V22: P | W22: A | X22: P | BL22: =COUNTIF(F22:BK22,"P") | BM22: =SUM((BL22/BL12)*100)
A23: 11 | B23: 2410313 | C23: 3122245002077 | D23: Raveena V K | E23: raveena2410313@ssn.edu.in | F23: P | G23: A | H23: A | I23: P | J23: P | K23: P | L23: A | M23: A | N23: A | O23: P | P23: P | Q23: P | R23: P | S23: A | T23: P | U23: A | V23: P | W23: A | X23: A | BL23: =COUNTIF(F23:BK23,"P") | BM23: =SUM((BL23/BL12)*100)
A24: 12 | B24: 2410581 | C24: 3122245002078 | D24: Ridhi R | E24: ridhi2410581@ssn.edu.in | F24: P | G24: P | H24: P | I24: P | J24: P | K24: P | L24: P | M24: P | N24: A | O24: P | P24: P | Q24: P | R24: P | S24: A | T24: A | U24: P | V24: P | W24: A | X24: P | BL24: =COUNTIF(F24:BK24,"P") | BM24: =SUM((BL24/BL12)*100)
A25: 13 | B25: 2410343 | C25: 3122245002079 | D25: Rishikumar Pitchiah Kalyanakumar | E25: rishikumar2410343@ssn.edu.in | F25: P | G25: P | H25: A | I25: P | J25: P | K25: P | L25: A | M25: A | N25: P | O25: P | P25: P | Q25: P | R25: P | S25: A | T25: P | U25: P | V25: P | W25: A | X25: A | BL25: =COUNTIF(F25:BK25,"P") | BM25: =SUM((BL25/BL12)*100)
A26: 14 | B26: 2410308 | C26: 3122245002080 | D26: Rithin Asvathama V | E26: rithinasvathama2410308@ssn.edu.in | F26: P | G26: P | H26: A | I26: P | J26: P | K26: P | L26: P | M26: P | N26: A | O26: A | P26: P | Q26: P | R26: P | S26: A | T26: P | U26: P | V26: P | W26: A | X26: P | BL26: =COUNTIF(F26:BK26,"P") | BM26: =SUM((BL26/BL12)*100)
A27: 15 | B27: 2410445 | C27: 3122245002081 | D27: Ritvik Kumar T | E27: ritvikkumar2410445@ssn.edu.in | F27: P | G27: P | H27: P | I27: P | J27: P | K27: P | L27: P | M27: P | N27: P | O27: P | P27: P | Q27: P | R27: P | S27: P | T27: P | U27: P | V27: P | W27: P | X27: P | BL27: =COUNTIF(F27:BK27,"P") | BM27: =SUM((BL27/BL12)*100)
A28: 16 | B28: 2410230 | C28: 3122245002082 | D28: Roja Sri R | E28: rojasri2410230@ssn.edu.in | F28: P | G28: P | H28: P | I28: P | J28: P | K28: P | L28: P | M28: P | N28: A | O28: P | P28: P | Q28: P | R28: P | S28: P | T28: P | U28: P | V28: P | W28: A | X28: P | BL28: =COUNTIF(F28:BK28,"P") | BM28: =SUM((BL28/BL12)*100)
A29: 17 | B29: 2410331 | C29: 3122245002083 | D29: Rovena Madharasi I | E29: rovenamadharasi2410331@ssn.edu.in | F29: P | G29: P | H29: P | I29: P | J29: P | K29: P | L29: P | M29: P | N29: P | O29: P | P29: P | Q29: P | R29: P | S29: P | T29: A | U29: P | V29: P | W29: A | X29: P | BL29: =COUNTIF(F29:BK29,"P") | BM29: =SUM((BL29/BL12)*100)
A30: 18 | B30: 2410229 | C30: 3122245002084 | D30: Sabarish S B | E30: sabarish2410229@ssn.edu.in | F30: P | G30: P | H30: P | I30: P | J30: P | K30: P | L30: P | M30: P | N30: A | O30: P | P30: P | Q30: P | R30: P | S30: A | T30: A | U30: P | V30: P | W30: A | X30: A | BL30: =COUNTIF(F30:BK30,"P") | BM30: =SUM((BL30/BL12)*100)
A31: 19 | B31: 2410984 | C31: 3122245002085 | D31: Sahana A | E31: sahana2410984@ssn.edu.in | F31: P | G31: P | H31: A | I31: P | J31: P | K31: A | L31: P | M31: P | N31: A | O31: P | P31: P | Q31: A | R31: P | S31: P | T31: P | U31: P | V31: A | W31: P | X31: P | BL31: =COUNTIF(F31:BK31,"P") | BM31: =SUM((BL31/BL12)*100)
A32: 20 | B32: 2410091 | C32: 3122245002086 | D32: Sandhya B | E32: sandhya2410091@ssn.edu.in | F32: P | G32: P | H32: P | I32: P | J32: P | K32: P | L32: P | M32: P | N32: A | O32: P | P32: P | Q32: P | R32: P | S32: P | T32: A | U32: P | V32: P | W32: P | X32: P | BL32: =COUNTIF(F32:BK32,"P") | BM32: =SUM((BL32/BL12)*100)
A33: 21 | B33: 2410706 | C33: 3122245002087 | D33: Sandhya S | E33: sandhya2410706@ssn.edu.in | F33: P | G33: P | H33: P | I33: P | J33: P | K33: P | L33: A | M33: A | N33: A | O33: P | P33: A | Q33: P | R33: P | S33: P | T33: P | U33: P | V33: A | W33: P | X33: A | BL33: =COUNTIF(F33:BK33,"P") | BM33: =SUM((BL33/BL12)*100)
A34: 22 | B34: 2410778 | C34: 3122245002088 | D34: Sangaraju Sathwik | E34: sangaraju2410778@ssn.edu.in | F34: P | G34: P | H34: A | I34: P | J34: P | K34: A | L34: A | M34: A | N34: A | O34: P | P34: A | Q34: A | R34: P | S34: A | T34: P | U34: A | V34: P | W34: A | X34: A | BL34: =COUNTIF(F34:BK34,"P") | BM34: =SUM((BL34/BL12)*100)
A35: 23 | B35: 2410162 | C35: 3122245002089 | D35: Sanjana Shankar | E35: sanjana2410162@ssn.edu.in | F35: P | G35: P | H35: A | I35: A | J35: A | K35: A | L35: A | M35: A | N35: A | O35: P | P35: P | Q35: P | R35: A | S35: A | T35: A | U35: A | V35: A | W35: A | X35: P | BL35: =COUNTIF(F35:BK35,"P") | BM35: =SUM((BL35/BL12)*100)
A36: 24 | B36: 2410514 | C36: 3122245002090 | D36: Sanjay J | E36: sanjay2410514@ssn.edu.in | F36: P | G36: P | H36: A | I36: A | J36: A | K36: P | L36: P | M36: P | N36: A | O36: P | P36: A | Q36: P | R36: P | S36: P | T36: A | U36: P | V36: P | W36: A | X36: A | BL36: =COUNTIF(F36:BK36,"P") | BM36: =SUM((BL36/BL12)*100)
A37: 25 | B37: 2410068 | C37: 3122245002091 | D37: Sanjay Raam S | E37: sanjayraam2410068@ssn.edu.in | F37: P | G37: P | H37: P | I37: A | J37: A | K37: A | L37: A | M37: A | N37: A | O37: A | P37: A | Q37: P | R37: P | S37: P | T37: A | U37: A | V37: P | W37: A | X37: P | BL37: =COUNTIF(F37:BK37,"P") | BM37: =SUM((BL37/BL12)*100)
A38: 26 | B38: 2410185 | C38: 3122245002092 | D38: Sanjay T | E38: sanjay2410185@ssn.edu.in | F38: P | G38: P | H38: P | I38: P | J38: P | K38: A | L38: A | M38: A | N38: A | O38: P | P38: P | Q38: P | R38: P | S38: P | T38: A | U38: P | V38: A | W38: A | X38: P | BL38: =COUNTIF(F38:BK38,"P") | BM38: =SUM((BL38/BL12)*100)
A39: 27 | B39: 2410988 | C39: 3122245002093 | D39: Santhosh Aaron C | E39: santhosh2410988@ssn.edu.in | F39: P | G39: P | H39: P | I39: A | J39: A | K39: P | L39: P | M39: P | N39: A | O39: P | P39: A | Q39: P | R39: P | S39: P | T39: A | U39: P | V39: P | W39: A | X39: A | BL39: =COUNTIF(F39:BK39,"P") | BM39: =SUM((BL39/BL12)*100)
A40: 28 | B40: 2410488 | C40: 3122245002094 | D40: Sarvesh K | E40: sarvesh2410488@ssn.edu.in | F40: P | G40: P | H40: A | I40: P | J40: P | K40: P | L40: P | M40: P | N40: A | O40: P | P40: P | Q40: A | R40: P | S40: A | T40: P | U40: P | V40: P | W40: P | X40: A | BL40: =COUNTIF(F40:BK40,"P") | BM40: =SUM((BL40/BL12)*100)
A41: 29 | B41: 2410076 | C41: 3122245002095 | D41: Sarvesh S | E41: sarvesh2410076@ssn.edu.in | F41: P | G41: P | H41: P | I41: P | J41: P | K41: P | L41: P | M41: P | N41: P | O41: P | P41: A | Q41: P | R41: P | S41: A | T41: A | U41: P | V41: P | W41: P | X41: P | BL41: =COUNTIF(F41:BK41,"P") | BM41: =SUM((BL41/BL12)*100)
A42: 30 | B42: 2410740 | C42: 3122245002096 | D42: Sarvesh S | E42: sarvesh2410740@ssn.edu.in | F42: P | G42: P | H42: P | I42: P | J42: P | K42: P | L42: P | M42: P | N42: A | O42: P | P42: A | Q42: P | R42: P | S42: P | T42: A | U42: P | V42: P | W42: P | X42: P | BL42: =COUNTIF(F42:BK42,"P") | BM42: =SUM((BL42/BL12)*100)
...

Sheet UIT3563
A1: Sri Sivasubramaniya Nadar College of Engineering, Kalavakkam - 603 110
A2: Department of Information Technology
A3: ATTENDANCE SHEET
A4: Class & Section : V SEM IT B
A5: Academic Year: 2026-2027 | AV5: Batch : 2024-28
A7: Sub Code & Sub Name : UIT3563 - Deep Learning Concepts and Architectures | AU7: ug2024-it@ssn.edu.in
A8: Staff Name : Dr. Nepoleon Keisham
F10: Mark "P" for presentees , "A" for absentees
A11: S.No | B11: Digital Id | C11: Register Number | D11: Name as per 12th Mark Sheet | E11: SSN Email ID | F11: Date
F12: 22/06/26 I&II hr | G12: 29/06/26 IIhr | H12: 1/7/26 Ihr | I12: 6/7/2026 Ihr & II hr | J12: 15/7/26 Ihr | K12: 20/7/26 IIhr | L12: 22/7/26 Ihr | M12: 29/7/26 1 hr | N12: 3/8/26 II hr | O12: 12/08/26 I hr | BI12: =COUNTA(F12:BH12)
A13: 1 | B13: 2410606 | C13: 3122245002067 | D13: Pragalya T | E13: pragalya2410606@ssn.edu.in | F13: P | G13: P | H13: P | I13: P | J13: P | K13: A | L13: P | M13: P | N13: A | O13: A | BI13: =COUNTIF(F13:BH13,"P") | BJ13: =SUM((BI13/BI12)*100)
A14: 2 | B14: 2410674 | C14: 3122245002068 | D14: Praghathish G T | E14: praghathish2410674@ssn.edu.in | F14: P | G14: P | H14: P | I14: A | J14: A | K14: A | L14: A | M14: P | N14: P | O14: A | BI14: =COUNTIF(F14:BH14,"P") | BJ14: =SUM((BI14/BI12)*100)
A15: 3 | B15: 2410080 | C15: 3122245002069 | D15: Pranav C K | E15: pranav2410080@ssn.edu.in | F15: P | G15: A | H15: A | I15: A | J15: A | K15: A | L15: A | M15: P | N15: A | O15: A | BI15: =COUNTIF(F15:BH15,"P") | BJ15: =SUM((BI15/BI12)*100)
A16: 4 | B16: 2410328 | C16: 3122245002070 | D16: Pranav Vasudevan | E16: pranav2410328@ssn.edu.in | F16: A | G16: A | H16: P | I16: A | J16: P | K16: A | L16: P | M16: P | N16: A | O16: A | BI16: =COUNTIF(F16:BH16,"P") | BJ16: =SUM((BI16/BI12)*100)
A17: 5 | B17: 2410738 | C17: 3122245002071 | D17: Radhakrishnan M | E17: radhakrishnan2410738@ssn.edu.in | F17: P | G17: P | H17: A | I17: P | J17: P | K17: A | L17: P | M17: A | N17: A | O17: A | BI17: =COUNTIF(F17:BH17,"P") | BJ17: =SUM((BI17/BI12)*100)
A18: 6 | B18: 2410786 | C18: 3122245002072 | D18: Raghul Krishna V | E18: raghulkrishna2410786@ssn.edu.in | F18: P | G18: P | H18: P | I18: P | J18: A | K18: A | L18: P | M18: P | N18: P | O18: P | BI18: =COUNTIF(F18:BH18,"P") | BJ18: =SUM((BI18/BI12)*100)
A19: 7 | B19: 2410441 | C19: 3122245002073 | D19: Ragul A | E19: ragul2410441@ssn.edu.in | F19: P | G19: P | H19: P | I19: A | J19: P | K19: A | L19: P | M19: P | N19: P | O19: P | BI19: =COUNTIF(F19:BH19,"P") | BJ19: =SUM((BI19/BI12)*100)
A20: 8 | B20: 2410834 | C20: 3122245002074 | D20: Ragunandhan M | E20: ragunandhan2410834@ssn.edu.in | F20: P | G20: P | H20: P | I20: P | J20: P | K20: P | L20: P | M20: P | N20: P | O20: P | BI20: =COUNTIF(F20:BH20,"P") | BJ20: =SUM((BI20/BI12)*100)
A21: 9 | B21: 2410098 | C21: 3122245002075 | D21: Rajkumar M | E21: rajkumar2410098@ssn.edu.in | F21: P | G21: A | H21: P | I21: P | J21: A | K21: A | L21: P | M21: A | N21: P | O21: A | BI21: =COUNTIF(F21:BH21,"P") | BJ21: =SUM((BI21/BI12)*100)
A22: 10 | B22: 2410632 | C22: 3122245002076 | D22: Ramakrishnan M R | E22: ramakrishnan2410632@ssn.edu.in | F22: P | G22: P | H22: P | I22: P | J22: A | K22: P | L22: P | M22: P | N22: P | O22: P | BI22: =COUNTIF(F22:BH22,"P") | BJ22: =SUM((BI22/BI12)*100)
A23: 11 | B23: 2410313 | C23: 3122245002077 | D23: Raveena V K | E23: raveena2410313@ssn.edu.in | F23: P | G23: P | H23: A | I23: P | J23: A | K23: A | L23: P | M23: A | N23: P | O23: A | BI23: =COUNTIF(F23:BH23,"P") | BJ23: =SUM((BI23/BI12)*100)
A24: 12 | B24: 2410581 | C24: 3122245002078 | D24: Ridhi R | E24: ridhi2410581@ssn.edu.in | F24: P | G24: P | H24: P | I24: P | J24: P | K24: A | L24: P | M24: A | N24: A | O24: A | BI24: =COUNTIF(F24:BH24,"P") | BJ24: =SUM((BI24/BI12)*100)
A25: 13 | B25: 2410343 | C25: 3122245002079 | D25: Rishikumar Pitchiah Kalyanakumar | E25: rishikumar2410343@ssn.edu.in | F25: A | G25: P | H25: A | I25: A | J25: A | K25: P | L25: P | M25: A | N25: P | O25: P | BI25: =COUNTIF(F25:BH25,"P") | BJ25: =SUM((BI25/BI12)*100)
A26: 14 | B26: 2410308 | C26: 3122245002080 | D26: Rithin Asvathama V | E26: rithinasvathama2410308@ssn.edu.in | F26: A | G26: P | H26: A | I26: P | J26: P | K26: A | L26: P | M26: A | N26: P | O26: A | BI26: =COUNTIF(F26:BH26,"P") | BJ26: =SUM((BI26/BI12)*100)
A27: 15 | B27: 2410445 | C27: 3122245002081 | D27: Ritvik Kumar T | E27: ritvikkumar2410445@ssn.edu.in | F27: P | G27: P | H27: P | I27: A | J27: P | K27: P | L27: P | M27: P | N27: P | O27: P | BI27: =COUNTIF(F27:BH27,"P") | BJ27: =SUM((BI27/BI12)*100)
A28: 16 | B28: 2410230 | C28: 3122245002082 | D28: Roja Sri R | E28: rojasri2410230@ssn.edu.in | F28: P | G28: P | H28: P | I28: A | J28: P | K28: A | L28: P | M28: P | N28: P | O28: A | BI28: =COUNTIF(F28:BH28,"P") | BJ28: =SUM((BI28/BI12)*100)
A29: 17 | B29: 2410331 | C29: 3122245002083 | D29: Rovena Madharasi I | E29: rovenamadharasi2410331@ssn.edu.in | F29: P | G29: P | H29: P | I29: P | J29: P | K29: P | L29: P | M29: P | N29: A | O29: P | BI29: =COUNTIF(F29:BH29,"P") | BJ29: =SUM((BI29/BI12)*100)
A30: 18 | B30: 2410229 | C30: 3122245002084 | D30: Sabarish S B | E30: sabarish2410229@ssn.edu.in | F30: P | G30: P | H30: P | I30: P | J30: P | K30: A | L30: P | M30: A | N30: A | O30: A | BI30: =COUNTIF(F30:BH30,"P") | BJ30: =SUM((BI30/BI12)*100)
A31: 19 | B31: 2410984 | C31: 3122245002085 | D31: Sahana A | E31: sahana2410984@ssn.edu.in | F31: A | G31: P | H31: A | I31: A | J31: P | K31: A | L31: P | M31: P | N31: P | O31: A | BI31: =COUNTIF(F31:BH31,"P") | BJ31: =SUM((BI31/BI12)*100)
A32: 20 | B32: 2410091 | C32: 3122245002086 | D32: Sandhya B | E32: sandhya2410091@ssn.edu.in | F32: P | G32: P | H32: P | I32: A | J32: P | K32: A | L32: P | M32: P | N32: A | O32: P | BI32: =COUNTIF(F32:BH32,"P") | BJ32: =SUM((BI32/BI12)*100)
A33: 21 | B33: 2410706 | C33: 3122245002087 | D33: Sandhya S | E33: sandhya2410706@ssn.edu.in | F33: P | G33: P | H33: P | I33: P | J33: A | K33: A | L33: A | M33: A | N33: P | O33: P | BI33: =COUNTIF(F33:BH33,"P") | BJ33: =SUM((BI33/BI12)*100)
A34: 22 | B34: 2410778 | C34: 3122245002088 | D34: Sangaraju Sathwik | E34: sangaraju2410778@ssn.edu.in | F34: A | G34: P | H34: A | I34: P | J34: A | K34: A | L34: A | M34: A | N34: P | O34: A | BI34: =COUNTIF(F34:BH34,"P") | BJ34: =SUM((BI34/BI12)*100)
A35: 23 | B35: 2410162 | C35: 3122245002089 | D35: Sanjana Shankar | E35: sanjana2410162@ssn.edu.in | F35: P | G35: A | H35: A | I35: A | J35: A | K35: A | L35: P | M35: A | N35: A | O35: A | BI35: =COUNTIF(F35:BH35,"P") | BJ35: =SUM((BI35/BI12)*100)
A36: 24 | B36: 2410514 | C36: 3122245002090 | D36: Sanjay J | E36: sanjay2410514@ssn.edu.in | F36: A | G36: P | H36: A | I36: A | J36: P | K36: A | L36: A | M36: A | N36: A | O36: A | BI36: =COUNTIF(F36:BH36,"P") | BJ36: =SUM((BI36/BI12)*100)
A37: 25 | B37: 2410068 | C37: 3122245002091 | D37: Sanjay Raam S | E37: sanjayraam2410068@ssn.edu.in | F37: P | G37: P | H37: P | I37: A | J37: A | K37: A | L37: A | M37: P | N37: A | O37: A | BI37: =COUNTIF(F37:BH37,"P") | BJ37: =SUM((BI37/BI12)*100)
A38: 26 | B38: 2410185 | C38: 3122245002092 | D38: Sanjay T | E38: sanjay2410185@ssn.edu.in | F38: P | G38: P | H38: P | I38: P | J38: A | K38: A | L38: P | M38: P | N38: A | O38: A | BI38: =COUNTIF(F38:BH38,"P") | BJ38: =SUM((BI38/BI12)*100)
A39: 27 | B39: 2410988 | C39: 3122245002093 | D39: Santhosh Aaron C | E39: santhosh2410988@ssn.edu.in | F39: P | G39: P | H39: P | I39: A | J39: A | K39: A | L39: A | M39: A | N39: A | O39: A | BI39: =COUNTIF(F39:BH39,"P") | BJ39: =SUM((BI39/BI12)*100)
A40: 28 | B40: 2410488 | C40: 3122245002094 | D40: Sarvesh K | E40: sarvesh2410488@ssn.edu.in | F40: P | G40: P | H40: A | I40: P | J40: A | K40: A | L40: P | M40: A | N40: P | O40: P | BI40: =COUNTIF(F40:BH40,"P") | BJ40: =SUM((BI40/BI12)*100)
A41: 29 | B41: 2410076 | C41: 3122245002095 | D41: Sarvesh S | E41: sarvesh2410076@ssn.edu.in | F41: P | G41: P | H41: P | I41: P | J41: P | K41: P | L41: A | M41: A | N41: A | O41: A | BI41: =COUNTIF(F41:BH41,"P") | BJ41: =SUM((BI41/BI12)*100)
A42: 30 | B42: 2410740 | C42: 3122245002096 | D42: Sarvesh S | E42: sarvesh2410740@ssn.edu.in | F42: P | G42: P | H42: P | I42: A | J42: P | K42: A | L42: A | M42: P | N42: A | O42: P | BI42: =COUNTIF(F42:BH42,"P") | BJ42: =SUM((BI42/BI12)*100)
...

Sheet UIT3501
A1: Sri Sivasubramaniya Nadar College of Engineering, Kalavakkam - 603 110
A2: Department of Information Technology
A3: ATTENDANCE SHEET
A4: Class & Section : V SEM IT B
A5: Academic Year: 2026-2027 | AV5: Batch : 2024-28
A7: Sub Code & Sub Name : UIT3501 - Automata Theory and Compiler Design | AU7: ug2024-it@ssn.edu.in
A8: Staff Name : Dr. P. Vasuki
F10: Mark "P" for presentees , "A" for absentees
A11: S.No | B11: Digital Id | C11: Register Number | D11: Name as per 12th Mark Sheet | E11: SSN Email ID | F11: Date
F12: 22.06.26 | G12: 26.06.26 | H12: 29.06.26 | I12: 1.07.26 | J12: 03.07.26 | K12: 06.07.06 | L12: 08.07.2026 | M12: 10.07.2026 | N12: 13.07.2026 | BI12: =COUNTA(F12:BH12)
A13: 1 | B13: 2410606 | C13: 3122245002067 | D13: Pragalya T | E13: pragalya2410606@ssn.edu.in | F13: P | G13: P | H13: P | I13: P | J13: P | K13: P | L13: P | M13: P | N13: P | BI13: =COUNTIF(F13:BH13,"P") | BJ13: =SUM((BI13/BI12)*100)
A14: 2 | B14: 2410674 | C14: 3122245002068 | D14: Praghathish G T | E14: praghathish2410674@ssn.edu.in | F14: P | G14: P | H14: P | I14: P | J14: P | K14: P | L14: P | M14: P | N14: P | BI14: =COUNTIF(F14:BH14,"P") | BJ14: =SUM((BI14/BI12)*100)
A15: 3 | B15: 2410080 | C15: 3122245002069 | D15: Pranav C K | E15: pranav2410080@ssn.edu.in | F15: P | G15: A | H15: A | I15: A | J15: A | K15: P | L15: P | M15: P | N15: P | BI15: =COUNTIF(F15:BH15,"P") | BJ15: =SUM((BI15/BI12)*100)
A16: 4 | B16: 2410328 | C16: 3122245002070 | D16: Pranav Vasudevan | E16: pranav2410328@ssn.edu.in | F16: A | G16: A | H16: A | I16: P | J16: A | K16: P | L16: P | M16: P | N16: P | BI16: =COUNTIF(F16:BH16,"P") | BJ16: =SUM((BI16/BI12)*100)
A17: 5 | B17: 2410738 | C17: 3122245002071 | D17: Radhakrishnan M | E17: radhakrishnan2410738@ssn.edu.in | F17: P | G17: P | H17: A | I17: A | J17: P | K17: P | L17: P | M17: P | N17: P | BI17: =COUNTIF(F17:BH17,"P") | BJ17: =SUM((BI17/BI12)*100)
A18: 6 | B18: 2410786 | C18: 3122245002072 | D18: Raghul Krishna V | E18: raghulkrishna2410786@ssn.edu.in | F18: P | G18: P | H18: P | I18: P | J18: P | K18: P | L18: P | M18: P | N18: P | BI18: =COUNTIF(F18:BH18,"P") | BJ18: =SUM((BI18/BI12)*100)
A19: 7 | B19: 2410441 | C19: 3122245002073 | D19: Ragul A | E19: ragul2410441@ssn.edu.in | F19: P | G19: P | H19: P | I19: P | J19: P | K19: P | L19: P | M19: P | N19: P | BI19: =COUNTIF(F19:BH19,"P") | BJ19: =SUM((BI19/BI12)*100)
A20: 8 | B20: 2410834 | C20: 3122245002074 | D20: Ragunandhan M | E20: ragunandhan2410834@ssn.edu.in | F20: P | G20: P | H20: P | I20: P | J20: P | K20: P | L20: P | M20: P | N20: P | BI20: =COUNTIF(F20:BH20,"P") | BJ20: =SUM((BI20/BI12)*100)
A21: 9 | B21: 2410098 | C21: 3122245002075 | D21: Rajkumar M | E21: rajkumar2410098@ssn.edu.in | F21: P | G21: P | H21: A | I21: P | J21: A | K21: P | L21: P | M21: P | N21: P | BI21: =COUNTIF(F21:BH21,"P") | BJ21: =SUM((BI21/BI12)*100)
A22: 10 | B22: 2410632 | C22: 3122245002076 | D22: Ramakrishnan M R | E22: ramakrishnan2410632@ssn.edu.in | F22: P | G22: P | H22: P | I22: P | J22: P | K22: P | L22: P | M22: P | N22: P | BI22: =COUNTIF(F22:BH22,"P") | BJ22: =SUM((BI22/BI12)*100)
A23: 11 | B23: 2410313 | C23: 3122245002077 | D23: Raveena V K | E23: raveena2410313@ssn.edu.in | F23: P | G23: P | H23: A | I23: A | J23: P | K23: P | L23: P | M23: P | N23: P | BI23: =COUNTIF(F23:BH23,"P") | BJ23: =SUM((BI23/BI12)*100)
A24: 12 | B24: 2410581 | C24: 3122245002078 | D24: Ridhi R | E24: ridhi2410581@ssn.edu.in | F24: P | G24: P | H24: P | I24: P | J24: A | K24: P | L24: P | M24: P | N24: P | BI24: =COUNTIF(F24:BH24,"P") | BJ24: =SUM((BI24/BI12)*100)
A25: 13 | B25: 2410343 | C25: 3122245002079 | D25: Rishikumar Pitchiah Kalyanakumar | E25: rishikumar2410343@ssn.edu.in | F25: A | G25: P | H25: P | I25: A | J25: P | K25: P | L25: P | M25: P | N25: P | Q25: 68 | BI25: =COUNTIF(F25:BH25,"P") | BJ25: =SUM((BI25/BI12)*100)
A26: 14 | B26: 2410308 | C26: 3122245002080 | D26: Rithin Asvathama V | E26: rithinasvathama2410308@ssn.edu.in | F26: A | G26: A | H26: P | I26: A | J26: P | K26: P | L26: P | M26: P | N26: P | Q26: 69 | BI26: =COUNTIF(F26:BH26,"P") | BJ26: =SUM((BI26/BI12)*100)
A27: 15 | B27: 2410445 | C27: 3122245002081 | D27: Ritvik Kumar T | E27: ritvikkumar2410445@ssn.edu.in | F27: P | G27: P | H27: P | I27: P | J27: A | K27: P | L27: P | M27: P | N27: P | Q27: 71 | BI27: =COUNTIF(F27:BH27,"P") | BJ27: =SUM((BI27/BI12)*100)
A28: 16 | B28: 2410230 | C28: 3122245002082 | D28: Roja Sri R | E28: rojasri2410230@ssn.edu.in | F28: P | G28: P | H28: P | I28: P | J28: P | K28: P | L28: P | M28: P | N28: P | Q28: 78 | BI28: =COUNTIF(F28:BH28,"P") | BJ28: =SUM((BI28/BI12)*100)
A29: 17 | B29: 2410331 | C29: 3122245002083 | D29: Rovena Madharasi I | E29: rovenamadharasi2410331@ssn.edu.in | F29: P | G29: P | H29: P | I29: P | J29: P | K29: P | L29: P | M29: P | N29: P | Q29: 79 | BI29: =COUNTIF(F29:BH29,"P") | BJ29: =SUM((BI29/BI12)*100)
A30: 18 | B30: 2410229 | C30: 3122245002084 | D30: Sabarish S B | E30: sabarish2410229@ssn.edu.in | F30: P | G30: P | H30: P | I30: P | J30: A | K30: P | L30: P | M30: P | N30: P | Q30: 82 | BI30: =COUNTIF(F30:BH30,"P") | BJ30: =SUM((BI30/BI12)*100)
A31: 19 | B31: 2410984 | C31: 3122245002085 | D31: Sahana A | E31: sahana2410984@ssn.edu.in | F31: A | G31: A | H31: P | I31: A | J31: P | K31: P | L31: P | M31: P | N31: P | Q31: 85 | BI31: =COUNTIF(F31:BH31,"P") | BJ31: =SUM((BI31/BI12)*100)
A32: 20 | B32: 2410091 | C32: 3122245002086 | D32: Sandhya B | E32: sandhya2410091@ssn.edu.in | F32: P | G32: P | H32: P | I32: P | J32: A | K32: P | L32: P | M32: P | N32: P | Q32: 86 | BI32: =COUNTIF(F32:BH32,"P") | BJ32: =SUM((BI32/BI12)*100)
A33: 21 | B33: 2410706 | C33: 3122245002087 | D33: Sandhya S | E33: sandhya2410706@ssn.edu.in | F33: P | G33: P | H33: P | I33: P | J33: P | K33: P | L33: P | M33: P | N33: P | Q33: 87 | BI33: =COUNTIF(F33:BH33,"P") | BJ33: =SUM((BI33/BI12)*100)
A34: 22 | B34: 2410778 | C34: 3122245002088 | D34: Sangaraju Sathwik | E34: sangaraju2410778@ssn.edu.in | F34: A | G34: P | H34: A | I34: A | J34: A | K34: P | L34: P | M34: P | N34: P | Q34: 88 | BI34: =COUNTIF(F34:BH34,"P") | BJ34: =SUM((BI34/BI12)*100)
A35: 23 | B35: 2410162 | C35: 3122245002089 | D35: Sanjana Shankar | E35: sanjana2410162@ssn.edu.in | F35: P | G35: A | H35: A | I35: P | J35: A | K35: P | L35: P | M35: P | N35: P | Q35: 89 | BI35: =COUNTIF(F35:BH35,"P") | BJ35: =SUM((BI35/BI12)*100)
A36: 24 | B36: 2410514 | C36: 3122245002090 | D36: Sanjay J | E36: sanjay2410514@ssn.edu.in | F36: A | G36: A | H36: P | I36: A | J36: P | K36: P | L36: P | M36: P | N36: P | Q36: 90 | BI36: =COUNTIF(F36:BH36,"P") | BJ36: =SUM((BI36/BI12)*100)
A37: 25 | B37: 2410068 | C37: 3122245002091 | D37: Sanjay Raam S | E37: sanjayraam2410068@ssn.edu.in | F37: P | G37: A | H37: P | I37: P | J37: A | K37: P | L37: P | M37: P | N37: P | Q37: 91 | BI37: =COUNTIF(F37:BH37,"P") | BJ37: =SUM((BI37/BI12)*100)
A38: 26 | B38: 2410185 | C38: 3122245002092 | D38: Sanjay T | E38: sanjay2410185@ssn.edu.in | F38: P | G38: P | H38: P | I38: P | J38: P | K38: P | L38: P | M38: P | N38: P | Q38: 92 | BI38: =COUNTIF(F38:BH38,"P") | BJ38: =SUM((BI38/BI12)*100)
A39: 27 | B39: 2410988 | C39: 3122245002093 | D39: Santhosh Aaron C | E39: santhosh2410988@ssn.edu.in | F39: P | G39: P | H39: P | I39: P | J39: P | K39: P | L39: P | M39: P | N39: P | Q39: 93 | BI39: =COUNTIF(F39:BH39,"P") | BJ39: =SUM((BI39/BI12)*100)
A40: 28 | B40: 2410488 | C40: 3122245002094 | D40: Sarvesh K | E40: sarvesh2410488@ssn.edu.in | F40: P | G40: P | H40: P | I40: A | J40: P | K40: P | L40: P | M40: P | N40: P | Q40: 96 | BI40: =COUNTIF(F40:BH40,"P") | BJ40: =SUM((BI40/BI12)*100)
A41: 29 | B41: 2410076 | C41: 3122245002095 | D41: Sarvesh S | E41: sarvesh2410076@ssn.edu.in | F41: P | G41: P | H41: P | I41: P | J41: P | K41: P | L41: P | M41: P | N41: P | Q41: 98 | BI41: =COUNTIF(F41:BH41,"P") | BJ41: =SUM((BI41/BI12)*100)
A42: 30 | B42: 2410740 | C42: 3122245002096 | D42: Sarvesh S | E42: sarvesh2410740@ssn.edu.in | F42: P | G42: P | H42: P | I42: P | J42: P | K42: P | L42: P | M42: P | N42: P | Q42: 101 | BI42: =COUNTIF(F42:BH42,"P") | BJ42: =SUM((BI42/BI12)*100)
...

Sheet UIT3515
A1: Sri Sivasubramaniya Nadar College of Engineering, Kalavakkam - 603 110
A2: Department of Information Technology
A3: ATTENDANCE SHEET
A4: Class & Section : V SEM IT B
A5: Academic Year: 2026-2027 | AV5: Batch : 2024-28
A7: Sub Code & Sub Name : UIT3515 - Dev Ops | AU7: ug2024-it@ssn.edu.in
A8: Staff Name : External Expert
F10: Mark "P" for presentees , "A" for absentees
A11: S.No | B11: Digital Id | C11: Register Number | D11: Name as per 12th Mark Sheet | E11: SSN Email ID | F11: Date
BI12: =COUNTA(F12:BH12)
A13: 1 | B13: 2410606 | C13: 3122245002067 | D13: Pragalya T | E13: pragalya2410606@ssn.edu.in | BI13: =COUNTIF(F13:BH13,"P") | BJ13: =SUM((BI13/BI12)*100)
A14: 2 | B14: 2410674 | C14: 3122245002068 | D14: Praghathish G T | E14: praghathish2410674@ssn.edu.in | BI14: =COUNTIF(F14:BH14,"P") | BJ14: =SUM((BI14/BI12)*100)
A15: 3 | B15: 2410080 | C15: 3122245002069 | D15: Pranav C K | E15: pranav2410080@ssn.edu.in | BI15: =COUNTIF(F15:BH15,"P") | BJ15: =SUM((BI15/BI12)*100)
A16: 4 | B16: 2410328 | C16: 3122245002070 | D16: Pranav Vasudevan | E16: pranav2410328@ssn.edu.in | BI16: =COUNTIF(F16:BH16,"P") | BJ16: =SUM((BI16/BI12)*100)
A17: 5 | B17: 2410738 | C17: 3122245002071 | D17: Radhakrishnan M | E17: radhakrishnan2410738@ssn.edu.in | BI17: =COUNTIF(F17:BH17,"P") | BJ17: =SUM((BI17/BI12)*100)
A18: 6 | B18: 2410786 | C18: 3122245002072 | D18: Raghul Krishna V | E18: raghulkrishna2410786@ssn.edu.in | BI18: =COUNTIF(F18:BH18,"P") | BJ18: =SUM((BI18/BI12)*100)
A19: 7 | B19: 2410441 | C19: 3122245002073 | D19: Ragul A | E19: ragul2410441@ssn.edu.in | BI19: =COUNTIF(F19:BH19,"P") | BJ19: =SUM((BI19/BI12)*100)
A20: 8 | B20: 2410834 | C20: 3122245002074 | D20: Ragunandhan M | E20: ragunandhan2410834@ssn.edu.in | BI20: =COUNTIF(F20:BH20,"P") | BJ20: =SUM((BI20/BI12)*100)
A21: 9 | B21: 2410098 | C21: 3122245002075 | D21: Rajkumar M | E21: rajkumar2410098@ssn.edu.in | BI21: =COUNTIF(F21:BH21,"P") | BJ21: =SUM((BI21/BI12)*100)
A22: 10 | B22: 2410632 | C22: 3122245002076 | D22: Ramakrishnan M R | E22: ramakrishnan2410632@ssn.edu.in | BI22: =COUNTIF(F22:BH22,"P") | BJ22: =SUM((BI22/BI12)*100)
A23: 11 | B23: 2410313 | C23: 3122245002077 | D23: Raveena V K | E23: raveena2410313@ssn.edu.in | BI23: =COUNTIF(F23:BH23,"P") | BJ23: =SUM((BI23/BI12)*100)
A24: 12 | B24: 2410581 | C24: 3122245002078 | D24: Ridhi R | E24: ridhi2410581@ssn.edu.in | BI24: =COUNTIF(F24:BH24,"P") | BJ24: =SUM((BI24/BI12)*100)
A25: 13 | B25: 2410343 | C25: 3122245002079 | D25: Rishikumar Pitchiah Kalyanakumar | E25: rishikumar2410343@ssn.edu.in | BI25: =COUNTIF(F25:BH25,"P") | BJ25: =SUM((BI25/BI12)*100)
A26: 14 | B26: 2410308 | C26: 3122245002080 | D26: Rithin Asvathama V | E26: rithinasvathama2410308@ssn.edu.in | BI26: =COUNTIF(F26:BH26,"P") | BJ26: =SUM((BI26/BI12)*100)
A27: 15 | B27: 2410445 | C27: 3122245002081 | D27: Ritvik Kumar T | E27: ritvikkumar2410445@ssn.edu.in | BI27: =COUNTIF(F27:BH27,"P") | BJ27: =SUM((BI27/BI12)*100)
A28: 16 | B28: 2410230 | C28: 3122245002082 | D28: Roja Sri R | E28: rojasri2410230@ssn.edu.in | BI28: =COUNTIF(F28:BH28,"P") | BJ28: =SUM((BI28/BI12)*100)
A29: 17 | B29: 2410331 | C29: 3122245002083 | D29: Rovena Madharasi I | E29: rovenamadharasi2410331@ssn.edu.in | BI29: =COUNTIF(F29:BH29,"P") | BJ29: =SUM((BI29/BI12)*100)
A30: 18 | B30: 2410229 | C30: 3122245002084 | D30: Sabarish S B | E30: sabarish2410229@ssn.edu.in | BI30: =COUNTIF(F30:BH30,"P") | BJ30: =SUM((BI30/BI12)*100)
A31: 19 | B31: 2410984 | C31: 3122245002085 | D31: Sahana A | E31: sahana2410984@ssn.edu.in | BI31: =COUNTIF(F31:BH31,"P") | BJ31: =SUM((BI31/BI12)*100)
A32: 20 | B32: 2410091 | C32: 3122245002086 | D32: Sandhya B | E32: sandhya2410091@ssn.edu.in | BI32: =COUNTIF(F32:BH32,"P") | BJ32: =SUM((BI32/BI12)*100)
A33: 21 | B33: 2410706 | C33: 3122245002087 | D33: Sandhya S | E33: sandhya2410706@ssn.edu.in | BI33: =COUNTIF(F33:BH33,"P") | BJ33: =SUM((BI33/BI12)*100)
A34: 22 | B34: 2410778 | C34: 3122245002088 | D34: Sangaraju Sathwik | E34: sangaraju2410778@ssn.edu.in | BI34: =COUNTIF(F34:BH34,"P") | BJ34: =SUM((BI34/BI12)*100)
A35: 23 | B35: 2410162 | C35: 3122245002089 | D35: Sanjana Shankar | E35: sanjana2410162@ssn.edu.in | BI35: =COUNTIF(F35:BH35,"P") | BJ35: =SUM((BI35/BI12)*100)
A36: 24 | B36: 2410514 | C36: 3122245002090 | D36: Sanjay J | E36: sanjay2410514@ssn.edu.in | BI36: =COUNTIF(F36:BH36,"P") | BJ36: =SUM((BI36/BI12)*100)
A37: 25 | B37: 2410068 | C37: 3122245002091 | D37: Sanjay Raam S | E37: sanjayraam2410068@ssn.edu.in | BI37: =COUNTIF(F37:BH37,"P") | BJ37: =SUM((BI37/BI12)*100)
A38: 26 | B38: 2410185 | C38: 3122245002092 | D38: Sanjay T | E38: sanjay2410185@ssn.edu.in | BI38: =COUNTIF(F38:BH38,"P") | BJ38: =SUM((BI38/BI12)*100)
A39: 27 | B39: 2410988 | C39: 3122245002093 | D39: Santhosh Aaron C | E39: santhosh2410988@ssn.edu.in | BI39: =COUNTIF(F39:BH39,"P") | BJ39: =SUM((BI39/BI12)*100)
A40: 28 | B40: 2410488 | C40: 3122245002094 | D40: Sarvesh K | E40: sarvesh2410488@ssn.edu.in | BI40: =COUNTIF(F40:BH40,"P") | BJ40: =SUM((BI40/BI12)*100)
A41: 29 | B41: 2410076 | C41: 3122245002095 | D41: Sarvesh S | E41: sarvesh2410076@ssn.edu.in | BI41: =COUNTIF(F41:BH41,"P") | BJ41: =SUM((BI41/BI12)*100)
A42: 30 | B42: 2410740 | C42: 3122245002096 | D42: Sarvesh S | E42: sarvesh2410740@ssn.edu.in | BI42: =COUNTIF(F42:BH42,"P") | BJ42: =SUM((BI42/BI12)*100)
...

Sheet UIT3519
A1: Sri Sivasubramaniya Nadar College of Engineering, Kalavakkam - 603 110
A2: Department of Information Technology
A3: ATTENDANCE SHEET
A4: Class & Section : V SEM IT B
A5: Academic Year: 2026-2027 | AV5: Batch : 2024-28
A7: Sub Code & Sub Name : UIT3519 - Introduction to Cyber Security | AU7: ug2024-it@ssn.edu.in
A8: Staff Name : External Expert
F10: Mark "P" for presentees , "A" for absentees
A11: S.No | B11: Digital Id | C11: Register Number | D11: Name as per 12th Mark Sheet | E11: SSN Email ID | F11: Date
BI12: =COUNTA(F12:BH12)
A13: 1 | B13: 2410606 | C13: 3122245002067 | D13: Pragalya T | E13: pragalya2410606@ssn.edu.in | BI13: =COUNTIF(F13:BH13,"P") | BJ13: =SUM((BI13/BI12)*100)
A14: 2 | B14: 2410674 | C14: 3122245002068 | D14: Praghathish G T | E14: praghathish2410674@ssn.edu.in | BI14: =COUNTIF(F14:BH14,"P") | BJ14: =SUM((BI14/BI12)*100)
A15: 3 | B15: 2410080 | C15: 3122245002069 | D15: Pranav C K | E15: pranav2410080@ssn.edu.in | BI15: =COUNTIF(F15:BH15,"P") | BJ15: =SUM((BI15/BI12)*100)
A16: 4 | B16: 2410328 | C16: 3122245002070 | D16: Pranav Vasudevan | E16: pranav2410328@ssn.edu.in | BI16: =COUNTIF(F16:BH16,"P") | BJ16: =SUM((BI16/BI12)*100)
A17: 5 | B17: 2410738 | C17: 3122245002071 | D17: Radhakrishnan M | E17: radhakrishnan2410738@ssn.edu.in | BI17: =COUNTIF(F17:BH17,"P") | BJ17: =SUM((BI17/BI12)*100)
A18: 6 | B18: 2410786 | C18: 3122245002072 | D18: Raghul Krishna V | E18: raghulkrishna2410786@ssn.edu.in | BI18: =COUNTIF(F18:BH18,"P") | BJ18: =SUM((BI18/BI12)*100)
A19: 7 | B19: 2410441 | C19: 3122245002073 | D19: Ragul A | E19: ragul2410441@ssn.edu.in | BI19: =COUNTIF(F19:BH19,"P") | BJ19: =SUM((BI19/BI12)*100)
A20: 8 | B20: 2410834 | C20: 3122245002074 | D20: Ragunandhan M | E20: ragunandhan2410834@ssn.edu.in | BI20: =COUNTIF(F20:BH20,"P") | BJ20: =SUM((BI20/BI12)*100)
A21: 9 | B21: 2410098 | C21: 3122245002075 | D21: Rajkumar M | E21: rajkumar2410098@ssn.edu.in | BI21: =COUNTIF(F21:BH21,"P") | BJ21: =SUM((BI21/BI12)*100)
A22: 10 | B22: 2410632 | C22: 3122245002076 | D22: Ramakrishnan M R | E22: ramakrishnan2410632@ssn.edu.in | BI22: =COUNTIF(F22:BH22,"P") | BJ22: =SUM((BI22/BI12)*100)
A23: 11 | B23: 2410313 | C23: 3122245002077 | D23: Raveena V K | E23: raveena2410313@ssn.edu.in | BI23: =COUNTIF(F23:BH23,"P") | BJ23: =SUM((BI23/BI12)*100)
A24: 12 | B24: 2410581 | C24: 3122245002078 | D24: Ridhi R | E24: ridhi2410581@ssn.edu.in | BI24: =COUNTIF(F24:BH24,"P") | BJ24: =SUM((BI24/BI12)*100)
A25: 13 | B25: 2410343 | C25: 3122245002079 | D25: Rishikumar Pitchiah Kalyanakumar | E25: rishikumar2410343@ssn.edu.in | BI25: =COUNTIF(F25:BH25,"P") | BJ25: =SUM((BI25/BI12)*100)
A26: 14 | B26: 2410308 | C26: 3122245002080 | D26: Rithin Asvathama V | E26: rithinasvathama2410308@ssn.edu.in | BI26: =COUNTIF(F26:BH26,"P") | BJ26: =SUM((BI26/BI12)*100)
A27: 15 | B27: 2410445 | C27: 3122245002081 | D27: Ritvik Kumar T | E27: ritvikkumar2410445@ssn.edu.in | BI27: =COUNTIF(F27:BH27,"P") | BJ27: =SUM((BI27/BI12)*100)
A28: 16 | B28: 2410230 | C28: 3122245002082 | D28: Roja Sri R | E28: rojasri2410230@ssn.edu.in | BI28: =COUNTIF(F28:BH28,"P") | BJ28: =SUM((BI28/BI12)*100)
A29: 17 | B29: 2410331 | C29: 3122245002083 | D29: Rovena Madharasi I | E29: rovenamadharasi2410331@ssn.edu.in | BI29: =COUNTIF(F29:BH29,"P") | BJ29: =SUM((BI29/BI12)*100)
A30: 18 | B30: 2410229 | C30: 3122245002084 | D30: Sabarish S B | E30: sabarish2410229@ssn.edu.in | BI30: =COUNTIF(F30:BH30,"P") | BJ30: =SUM((BI30/BI12)*100)
A31: 19 | B31: 2410984 | C31: 3122245002085 | D31: Sahana A | E31: sahana2410984@ssn.edu.in | BI31: =COUNTIF(F31:BH31,"P") | BJ31: =SUM((BI31/BI12)*100)
A32: 20 | B32: 2410091 | C32: 3122245002086 | D32: Sandhya B | E32: sandhya2410091@ssn.edu.in | BI32: =COUNTIF(F32:BH32,"P") | BJ32: =SUM((BI32/BI12)*100)
A33: 21 | B33: 2410706 | C33: 3122245002087 | D33: Sandhya S | E33: sandhya2410706@ssn.edu.in | BI33: =COUNTIF(F33:BH33,"P") | BJ33: =SUM((BI33/BI12)*100)
A34: 22 | B34: 2410778 | C34: 3122245002088 | D34: Sangaraju Sathwik | E34: sangaraju2410778@ssn.edu.in | BI34: =COUNTIF(F34:BH34,"P") | BJ34: =SUM((BI34/BI12)*100)
A35: 23 | B35: 2410162 | C35: 3122245002089 | D35: Sanjana Shankar | E35: sanjana2410162@ssn.edu.in | BI35: =COUNTIF(F35:BH35,"P") | BJ35: =SUM((BI35/BI12)*100)
A36: 24 | B36: 2410514 | C36: 3122245002090 | D36: Sanjay J | E36: sanjay2410514@ssn.edu.in | BI36: =COUNTIF(F36:BH36,"P") | BJ36: =SUM((BI36/BI12)*100)
A37: 25 | B37: 2410068 | C37: 3122245002091 | D37: Sanjay Raam S | E37: sanjayraam2410068@ssn.edu.in | BI37: =COUNTIF(F37:BH37,"P") | BJ37: =SUM((BI37/BI12)*100)
A38: 26 | B38: 2410185 | C38: 3122245002092 | D38: Sanjay T | E38: sanjay2410185@ssn.edu.in | BI38: =COUNTIF(F38:BH38,"P") | BJ38: =SUM((BI38/BI12)*100)
A39: 27 | B39: 2410988 | C39: 3122245002093 | D39: Santhosh Aaron C | E39: santhosh2410988@ssn.edu.in | BI39: =COUNTIF(F39:BH39,"P") | BJ39: =SUM((BI39/BI12)*100)
A40: 28 | B40: 2410488 | C40: 3122245002094 | D40: Sarvesh K | E40: sarvesh2410488@ssn.edu.in | BI40: =COUNTIF(F40:BH40,"P") | BJ40: =SUM((BI40/BI12)*100)
A41: 29 | B41: 2410076 | C41: 3122245002095 | D41: Sarvesh S | E41: sarvesh2410076@ssn.edu.in | BI41: =COUNTIF(F41:BH41,"P") | BJ41: =SUM((BI41/BI12)*100)
A42: 30 | B42: 2410740 | C42: 3122245002096 | D42: Sarvesh S | E42: sarvesh2410740@ssn.edu.in | BI42: =COUNTIF(F42:BH42,"P") | BJ42: =SUM((BI42/BI12)*100)
...

Sheet UIT3517
A1: Sri Sivasubramaniya Nadar College of Engineering, Kalavakkam - 603 110
A2: Department of Information Technology
A3: ATTENDANCE SHEET
A4: Class & Section : V SEM IT B
A5: Academic Year: 2026-2027 | AV5: Batch : 2024-28
A7: Sub Code & Sub Name : UIT3517 - Mini Project (Software Development Project – II) | AU7: ug2024-it@ssn.edu.in
A8: Staff Name :Dr. A. Shahina, Dr. R. Srinivasan, Dr. S. Karthika, Dr. H. Sabireen, Dr. Arige Sumanth, Dr. Mahabub Hasan Mahalat, Dr. Irshed Hussain
F10: Mark "P" for presentees , "A" for absentees
A11: S.No | B11: Digital Id | C11: Register Number | D11: Name as per 12th Mark Sheet | E11: SSN Email ID | F11: Date
BI12: =COUNTA(F12:BH12)
A13: 1 | B13: 2410606 | C13: 3122245002067 | D13: Pragalya T | E13: pragalya2410606@ssn.edu.in | BI13: =COUNTIF(F13:BH13,"P") | BJ13: =SUM((BI13/BI12)*100)
A14: 2 | B14: 2410674 | C14: 3122245002068 | D14: Praghathish G T | E14: praghathish2410674@ssn.edu.in | BI14: =COUNTIF(F14:BH14,"P") | BJ14: =SUM((BI14/BI12)*100)
A15: 3 | B15: 2410080 | C15: 3122245002069 | D15: Pranav C K | E15: pranav2410080@ssn.edu.in | BI15: =COUNTIF(F15:BH15,"P") | BJ15: =SUM((BI15/BI12)*100)
A16: 4 | B16: 2410328 | C16: 3122245002070 | D16: Pranav Vasudevan | E16: pranav2410328@ssn.edu.in | BI16: =COUNTIF(F16:BH16,"P") | BJ16: =SUM((BI16/BI12)*100)
A17: 5 | B17: 2410738 | C17: 3122245002071 | D17: Radhakrishnan M | E17: radhakrishnan2410738@ssn.edu.in | BI17: =COUNTIF(F17:BH17,"P") | BJ17: =SUM((BI17/BI12)*100)
A18: 6 | B18: 2410786 | C18: 3122245002072 | D18: Raghul Krishna V | E18: raghulkrishna2410786@ssn.edu.in | BI18: =COUNTIF(F18:BH18,"P") | BJ18: =SUM((BI18/BI12)*100)
A19: 7 | B19: 2410441 | C19: 3122245002073 | D19: Ragul A | E19: ragul2410441@ssn.edu.in | BI19: =COUNTIF(F19:BH19,"P") | BJ19: =SUM((BI19/BI12)*100)
A20: 8 | B20: 2410834 | C20: 3122245002074 | D20: Ragunandhan M | E20: ragunandhan2410834@ssn.edu.in | BI20: =COUNTIF(F20:BH20,"P") | BJ20: =SUM((BI20/BI12)*100)
A21: 9 | B21: 2410098 | C21: 3122245002075 | D21: Rajkumar M | E21: rajkumar2410098@ssn.edu.in | BI21: =COUNTIF(F21:BH21,"P") | BJ21: =SUM((BI21/BI12)*100)
A22: 10 | B22: 2410632 | C22: 3122245002076 | D22: Ramakrishnan M R | E22: ramakrishnan2410632@ssn.edu.in | BI22: =COUNTIF(F22:BH22,"P") | BJ22: =SUM((BI22/BI12)*100)
A23: 11 | B23: 2410313 | C23: 3122245002077 | D23: Raveena V K | E23: raveena2410313@ssn.edu.in | BI23: =COUNTIF(F23:BH23,"P") | BJ23: =SUM((BI23/BI12)*100)
A24: 12 | B24: 2410581 | C24: 3122245002078 | D24: Ridhi R | E24: ridhi2410581@ssn.edu.in | BI24: =COUNTIF(F24:BH24,"P") | BJ24: =SUM((BI24/BI12)*100)
A25: 13 | B25: 2410343 | C25: 3122245002079 | D25: Rishikumar Pitchiah Kalyanakumar | E25: rishikumar2410343@ssn.edu.in | BI25: =COUNTIF(F25:BH25,"P") | BJ25: =SUM((BI25/BI12)*100)
A26: 14 | B26: 2410308 | C26: 3122245002080 | D26: Rithin Asvathama V | E26: rithinasvathama2410308@ssn.edu.in | BI26: =COUNTIF(F26:BH26,"P") | BJ26: =SUM((BI26/BI12)*100)
A27: 15 | B27: 2410445 | C27: 3122245002081 | D27: Ritvik Kumar T | E27: ritvikkumar2410445@ssn.edu.in | BI27: =COUNTIF(F27:BH27,"P") | BJ27: =SUM((BI27/BI12)*100)
A28: 16 | B28: 2410230 | C28: 3122245002082 | D28: Roja Sri R | E28: rojasri2410230@ssn.edu.in | BI28: =COUNTIF(F28:BH28,"P") | BJ28: =SUM((BI28/BI12)*100)
A29: 17 | B29: 2410331 | C29: 3122245002083 | D29: Rovena Madharasi I | E29: rovenamadharasi2410331@ssn.edu.in | BI29: =COUNTIF(F29:BH29,"P") | BJ29: =SUM((BI29/BI12)*100)
A30: 18 | B30: 2410229 | C30: 3122245002084 | D30: Sabarish S B | E30: sabarish2410229@ssn.edu.in | BI30: =COUNTIF(F30:BH30,"P") | BJ30: =SUM((BI30/BI12)*100)
A31: 19 | B31: 2410984 | C31: 3122245002085 | D31: Sahana A | E31: sahana2410984@ssn.edu.in | BI31: =COUNTIF(F31:BH31,"P") | BJ31: =SUM((BI31/BI12)*100)
A32: 20 | B32: 2410091 | C32: 3122245002086 | D32: Sandhya B | E32: sandhya2410091@ssn.edu.in | BI32: =COUNTIF(F32:BH32,"P") | BJ32: =SUM((BI32/BI12)*100)
A33: 21 | B33: 2410706 | C33: 3122245002087 | D33: Sandhya S | E33: sandhya2410706@ssn.edu.in | BI33: =COUNTIF(F33:BH33,"P") | BJ33: =SUM((BI33/BI12)*100)
A34: 22 | B34: 2410778 | C34: 3122245002088 | D34: Sangaraju Sathwik | E34: sangaraju2410778@ssn.edu.in | BI34: =COUNTIF(F34:BH34,"P") | BJ34: =SUM((BI34/BI12)*100)
A35: 23 | B35: 2410162 | C35: 3122245002089 | D35: Sanjana Shankar | E35: sanjana2410162@ssn.edu.in | BI35: =COUNTIF(F35:BH35,"P") | BJ35: =SUM((BI35/BI12)*100)
A36: 24 | B36: 2410514 | C36: 3122245002090 | D36: Sanjay J | E36: sanjay2410514@ssn.edu.in | BI36: =COUNTIF(F36:BH36,"P") | BJ36: =SUM((BI36/BI12)*100)
A37: 25 | B37: 2410068 | C37: 3122245002091 | D37: Sanjay Raam S | E37: sanjayraam2410068@ssn.edu.in | BI37: =COUNTIF(F37:BH37,"P") | BJ37: =SUM((BI37/BI12)*100)
A38: 26 | B38: 2410185 | C38: 3122245002092 | D38: Sanjay T | E38: sanjay2410185@ssn.edu.in | BI38: =COUNTIF(F38:BH38,"P") | BJ38: =SUM((BI38/BI12)*100)
A39: 27 | B39: 2410988 | C39: 3122245002093 | D39: Santhosh Aaron C | E39: santhosh2410988@ssn.edu.in | BI39: =COUNTIF(F39:BH39,"P") | BJ39: =SUM((BI39/BI12)*100)
A40: 28 | B40: 2410488 | C40: 3122245002094 | D40: Sarvesh K | E40: sarvesh2410488@ssn.edu.in | BI40: =COUNTIF(F40:BH40,"P") | BJ40: =SUM((BI40/BI12)*100)
A41: 29 | B41: 2410076 | C41: 3122245002095 | D41: Sarvesh S | E41: sarvesh2410076@ssn.edu.in | BI41: =COUNTIF(F41:BH41,"P") | BJ41: =SUM((BI41/BI12)*100)
A42: 30 | B42: 2410740 | C42: 3122245002096 | D42: Sarvesh S | E42: sarvesh2410740@ssn.edu.in | BI42: =COUNTIF(F42:BH42,"P") | BJ42: =SUM((BI42/BI12)*100)
...

Sheet SUBJECT SUMMARY SHEET
C2: SUBJECTWISE SUMMARY SHEET
A4: Class & Section : V SEM IT A
B5: Subject code | C5: Subject Name | D5: Faculty Name | E5: Total No of students | F5: Total No of Presentees | G5: Percentage
B6: UIT3561 | C6: Full Stack Web Development | D6: Mr. Sankar Santhamoorthy(T) & Dr. K. R. Uthayan(P) | E6: =UIT3561!F91 | F6: =UIT3561!F92 | G6: =SUM((F6/E6)*100)
B7: UIT3562 | C7: Principles of Operating Systems | D7: Dr. I. Joe Louis Paul(T) & Dr. S. Mohanavalli(P) | E7: =UIT3562!F91 | F7: =UIT3562!F92 | G7: =SUM((F7/E7)*100)
B8: UIT3563 | C8: Deep Learning Concepts and Architectures | D8: Dr. Nepoleon Keisham(T) & Dr. A. Shahina(P) | E8: =UIT3563!F91 | F8: =UIT3563!F92 | G8: =SUM((F8/E8)*100)
B9: UIT3501 | C9: Automata Theory and Compiler Design | D9: Dr. P. Vasuki | E9: =UIT3501!F91 | F9: =UIT3501!F92 | G9: =SUM((F9/E9)*100)
B10: UIT3515 | C10: Dev Ops | D10: External Expert | E10: =UIT3515!F91 | F10: =UIT3515!F92 | G10: =SUM((F10/E10)*100)
B11: UIT3519 | C11: Introduction to Cyber Security | D11: External Expert | E11: =UIT3519!F91 | F11: =UIT3519!F92 | G11: =SUM((F11/E11)*100)
B12: UIT3517 | C12: Mini Project (Software Development Project – II) | D12: Dr. A. Shahina, Dr. R. Srinivasan, Dr. S. Karthika, Dr. H. Sabireen, Dr. Arige Sumanth, Dr. Mahabub Hasan Mahalat, Dr. Irshed Hussain | E12: =UIT3517!F91 | F12: =UIT3517!F92 | G12: =SUM((F12/E12)*100)
R41: Dr. P. Jaish
R42: Dr. S. I. Davis Presley
R43: Dr. M. Mohamed Iqbal(T) & Dr. Mahabub Hasan Mahalat(P)
R44: Dr. N. Kalaichelvi
R45: Dr. G. Sornavalli(T) & Dr. N. Radha
R46: Dr. V. Tamilmani
R47: Dr. V. Sivamurugan(T) & Dr. Arige Sumanth(P)
R48: Dr. Arige Sumanth
R49: Dr. N. Kalaichelvi & Dr. P. Vasuki
R50: External Expert

Sheet STUDENT WISE SUMMARY SHEET
A1: Sri Sivasubramaniya Nadar College of Engineering, Kalavakkam - 603 110
A2: Department of Information Technology
A3: STUDENT WISE SUMMARY SHEET
A4: Class & Section : V SEM IT B
A5: Academic Year: 2026-2027
A8: S.No | B8: Digital Id | C8: Register Number | D8: Name as per 12th Mark Sheet | E8: SSN Email ID
A10: 1 | B10: 2410606 | C10: 3122245002067 | D10: Pragalya T | E10: pragalya2410606@ssn.edu.in | F10: =SUM(UIT3561!BJ12+UIT3562!BL12+UIT3563!BI12+UIT3501!BI12+UIT3515!BI12+UIT3519!BI12+UIT3517!BI12) | G10: =SUM(UIT3561!BJ13+UIT3562!BL13+UIT3563!BI13+UIT3501!BI13+UIT3515!BI13+UIT3519!BI13+UIT3517!BI13) | H10: =SUM((G10/F10)*100)
A11: 2 | B11: 2410674 | C11: 3122245002068 | D11: Praghathish G T | E11: praghathish2410674@ssn.edu.in | F11: =SUM(UIT3561!BJ13+UIT3562!BL13+UIT3563!BI13+UIT3501!BI13+UIT3515!BI13+UIT3519!BI13+UIT3517!BI13) | G11: =SUM(UIT3561!BJ14+UIT3562!BL14+UIT3563!BI14+UIT3501!BI14+UIT3515!BI14+UIT3519!BI14+UIT3517!BI14) | H11: =SUM((G11/F11)*100)
A12: 3 | B12: 2410080 | C12: 3122245002069 | D12: Pranav C K | E12: pranav2410080@ssn.edu.in | F12: =SUM(UIT3561!BJ14+UIT3562!BL14+UIT3563!BI14+UIT3501!BI14+UIT3515!BI14+UIT3519!BI14+UIT3517!BI14) | G12: =SUM(UIT3561!BJ15+UIT3562!BL15+UIT3563!BI15+UIT3501!BI15+UIT3515!BI15+UIT3519!BI15+UIT3517!BI15) | H12: =SUM((G12/F12)*100)
A13: 4 | B13: 2410328 | C13: 3122245002070 | D13: Pranav Vasudevan | E13: pranav2410328@ssn.edu.in | F13: =SUM(UIT3561!BJ15+UIT3562!BL15+UIT3563!BI15+UIT3501!BI15+UIT3515!BI15+UIT3519!BI15+UIT3517!BI15) | G13: =SUM(UIT3561!BJ16+UIT3562!BL16+UIT3563!BI16+UIT3501!BI16+UIT3515!BI16+UIT3519!BI16+UIT3517!BI16) | H13: =SUM((G13/F13)*100)
A14: 5 | B14: 2410738 | C14: 3122245002071 | D14: Radhakrishnan M | E14: radhakrishnan2410738@ssn.edu.in | F14: =SUM(UIT3561!BJ16+UIT3562!BL16+UIT3563!BI16+UIT3501!BI16+UIT3515!BI16+UIT3519!BI16+UIT3517!BI16) | G14: =SUM(UIT3561!BJ17+UIT3562!BL17+UIT3563!BI17+UIT3501!BI17+UIT3515!BI17+UIT3519!BI17+UIT3517!BI17) | H14: =SUM((G14/F14)*100)
A15: 6 | B15: 2410786 | C15: 3122245002072 | D15: Raghul Krishna V | E15: raghulkrishna2410786@ssn.edu.in | F15: =SUM(UIT3561!BJ17+UIT3562!BL17+UIT3563!BI17+UIT3501!BI17+UIT3515!BI17+UIT3519!BI17+UIT3517!BI17) | G15: =SUM(UIT3561!BJ18+UIT3562!BL18+UIT3563!BI18+UIT3501!BI18+UIT3515!BI18+UIT3519!BI18+UIT3517!BI18) | H15: =SUM((G15/F15)*100)
A16: 7 | B16: 2410441 | C16: 3122245002073 | D16: Ragul A | E16: ragul2410441@ssn.edu.in | F16: =SUM(UIT3561!BJ18+UIT3562!BL18+UIT3563!BI18+UIT3501!BI18+UIT3515!BI18+UIT3519!BI18+UIT3517!BI18) | G16: =SUM(UIT3561!BJ19+UIT3562!BL19+UIT3563!BI19+UIT3501!BI19+UIT3515!BI19+UIT3519!BI19+UIT3517!BI19) | H16: =SUM((G16/F16)*100)
A17: 8 | B17: 2410834 | C17: 3122245002074 | D17: Ragunandhan M | E17: ragunandhan2410834@ssn.edu.in | F17: =SUM(UIT3561!BJ19+UIT3562!BL19+UIT3563!BI19+UIT3501!BI19+UIT3515!BI19+UIT3519!BI19+UIT3517!BI19) | G17: =SUM(UIT3561!BJ20+UIT3562!BL20+UIT3563!BI20+UIT3501!BI20+UIT3515!BI20+UIT3519!BI20+UIT3517!BI20) | H17: =SUM((G17/F17)*100)
A18: 9 | B18: 2410098 | C18: 3122245002075 | D18: Rajkumar M | E18: rajkumar2410098@ssn.edu.in | F18: =SUM(UIT3561!BJ20+UIT3562!BL20+UIT3563!BI20+UIT3501!BI20+UIT3515!BI20+UIT3519!BI20+UIT3517!BI20) | G18: =SUM(UIT3561!BJ21+UIT3562!BL21+UIT3563!BI21+UIT3501!BI21+UIT3515!BI21+UIT3519!BI21+UIT3517!BI21) | H18: =SUM((G18/F18)*100)
A19: 10 | B19: 2410632 | C19: 3122245002076 | D19: Ramakrishnan M R | E19: ramakrishnan2410632@ssn.edu.in | F19: =SUM(UIT3561!BJ21+UIT3562!BL21+UIT3563!BI21+UIT3501!BI21+UIT3515!BI21+UIT3519!BI21+UIT3517!BI21) | G19: =SUM(UIT3561!BJ22+UIT3562!BL22+UIT3563!BI22+UIT3501!BI22+UIT3515!BI22+UIT3519!BI22+UIT3517!BI22) | H19: =SUM((G19/F19)*100)
A20: 11 | B20: 2410313 | C20: 3122245002077 | D20: Raveena V K | E20: raveena2410313@ssn.edu.in | F20: =SUM(UIT3561!BJ22+UIT3562!BL22+UIT3563!BI22+UIT3501!BI22+UIT3515!BI22+UIT3519!BI22+UIT3517!BI22) | G20: =SUM(UIT3561!BJ23+UIT3562!BL23+UIT3563!BI23+UIT3501!BI23+UIT3515!BI23+UIT3519!BI23+UIT3517!BI23) | H20: =SUM((G20/F20)*100)
A21: 12 | B21: 2410581 | C21: 3122245002078 | D21: Ridhi R | E21: ridhi2410581@ssn.edu.in | F21: =SUM(UIT3561!BJ23+UIT3562!BL23+UIT3563!BI23+UIT3501!BI23+UIT3515!BI23+UIT3519!BI23+UIT3517!BI23) | G21: =SUM(UIT3561!BJ24+UIT3562!BL24+UIT3563!BI24+UIT3501!BI24+UIT3515!BI24+UIT3519!BI24+UIT3517!BI24) | H21: =SUM((G21/F21)*100)
... A80: 71 | B80: 2412001 | C80: 3122245002310 | D80: Sundararajan R | E80: sundararajan2412001@ssn.edu.in | F80: =SUM(UIT3561!BJ82+UIT3562!BL82+UIT3563!BI82+UIT3501!BI82+UIT3515!BI82+UIT3519!BI82+UIT3517!BI82) | G80: =SUM(UIT3561!BJ83+UIT3562!BL83+UIT3563!BI83+UIT3501!BI83+UIT3515!BI83+UIT3519!BI83+UIT3517!BI83) | H80: =SUM((G80/F80)*100)
E85: Above 75% (Eligible) | H85: =COUNTIF(H11:H80,">=75")
E86: 74% to 65% (Eligible to MC submitted) | H86: =COUNTIFS(H11:H80,">=65",H11:H80,"<=74")
E87: Below 65% (Ineligible) | H87: =COUNTIF(H11:H80,"<65")

Sheet HGHG
A1: SSN College of Engineering, Kalavakkam - 603 110
A2: Department of Information Technology
A3: NAME LIST
A4: Class & Section : VI SEM IT B
A5: Academic Year: 2014-2015
C6: Batch: 2012-2016
A7: Sub Code & Sub Name :
A8: Staff Name :
A10: SL. NO | B10: REG. NO. | C10: NAME
A11: 1 | B11: 312212205065 | C11: NEIL S MANOJ
A12: 2 | B12: 312212205066 | C12: NITHISH S
A13: 3 | B13: 312212205071 | C13: POOJETHA DEVI S
A14: 4 | B14: 312212205073 | C14: PRADEEBA M
A15: 5 | B15: 312212205078 | C15: RAGAVI K
A16: 6 | B16: 312212205087 | C16: SANDEEP JOEL A
A17: 7 | B17: 312212205095 | C17: SOUMYA A
A18: 8 | B18: 312212205102 | C18: SUSHMITHA S
A19: 9 | B19: 312212205103 | C19: SUSMA V
A20: 10 | B20: 312212205111 | C20: VARALAKSHMI V
A21: 11 | B21: 312212205115 | C21: VIDHYALAKSHMI K
A22: 12 | B22: 312212205116 | C22: VIGNESH R
... A32: 22 | B32: 312212205318 | C32: VISWESH V

Sheet Open Elective
A1: SSN College of Engineering, Kalavakkam - 603 110
A2: Department of Information Technology
A3: OPEN ELECTIVE NAMELIST
A4: Class & Section : VI SEM IT
A5: Academic Year: 2020-2021
D6: Batch: 2018-2022
A7: Sub Code & Sub Name :
A8: Staff Name :
A10: SL. NO | B10: REG. NO. | C10: NAME | D10: OPEN ELECTIVE SUBJECT
A11: 1 | B11: 185002001 | C11: Aadhithya B.Kailash | D11: UIT1622 - Speech Processing
A12: 2 | B12: 185002003 | C12: Adithya R | D12: UIT1622 - Speech Processing
A13: 3 | B13: 185002007 | C13: Akarvin Raja Prajan S A J | D13: UIT1622 - Speech Processing
A14: 4 | B14: 185002011 | C14: Amrith M | D14: UIT1622 - Speech Processing
A15: 5 | B15: 185002016 | C15: R. Arun Kumar | D15: UIT1622 - Speech Processing
A16: 6 | B16: 185002018 | C16: M Badri Narayanan | D16: UIT1622 - Speech Processing
A17: 7 | B17: 185002020 | C17: Yagnavi | D17: UIT1622 - Speech Processing
A18: 8 | B18: 185002029 | C18: Ghanta Sandhya Rani | D18: UIT1622 - Speech Processing
A19: 9 | B19: 185002049 | C19: S. Keertivaas | D19: UIT1622 - Speech Processing
A20: 10 | B20: 185002014 | C20: R Aravind Angappan | D20: UIT1621 - Real Time Embedded Systems
A21: 11 | B21: 185002015 | C21: ARUN KS | D21: UIT1621 - Real Time Embedded Systems
A22: 12 | B22: 185002017 | C22: Arun Laxman A | D22: UIT1621 - Real Time Embedded Systems
... A142: 132 | B142: 185002309 | C142: Siva Ganesh N | D142: UIT1625 - Analysis and Design of Service Oriented Architecture
